Workbook

Sheet WACC
B2: Weighted Average Cost of Capital
B4: All figures are in INR unless stated otherwise
B6: Peer Comps
G7: Debt / | H7: Debt / | I7: Levered | J7: Unlevered
B8: Name of the Comp | C8: Country | D8: Total Debt | E8: Total Equity | F8: Tax Rate 1 | G8: Equity | H8: Capital | I8: Beta 2 | J8: Beta 3
B10: JSW Steel | C10: India | D10: 98752 | E10: 245902.62 | F10: 0.3 | G10: =D10/E10 -> 0.40158987 | H10: =D10/(D10+E10) -> 0.28652452 | I10: ='peers Levered Beta - regression'!E5 -> 1.1292529 | J10: =I10/(1+(1-F10)*(G10)) -> 0.88146242
B11: Tata Steel | C11: India | D11: 94801.05 | E11: 189712.16 | F11: 0.3 | G11: =D11/E11 -> 0.49970993 | H11: =D11/(D11+E11) -> 0.33320439 | I11: ='peers Levered Beta - regression'!E6 -> 1.3540647 | J11: =I11/(1+(1-F11)*(G11)) -> 1.0031618
B12: Jindal Steel | C12: India | D12: 18406.08 | E12: 91711.02 | F12: 0.3 | G12: =D12/E12 -> 0.20069649 | H12: =D12/(D12+E12) -> 0.16715006 | I12: ='peers Levered Beta - regression'!E7 -> 1.3052257 | J12: =I12/(1+(1-F12)*(G12)) -> 1.1444453
B13: S A I L | C13: India | D13: 36933.94 | E13: 52655.94 | F13: 0.3 | G13: =D13/E13 -> 0.7014202 | H13: =D13/(D13+E13) -> 0.41225571 | I13: ='peers Levered Beta - regression'!E8 -> 1.5705924 | J13: =I13/(1+(1-F13)*(G13)) -> 1.053386
B14: Sarda Energy | C14: India | D14: 2861.05 | E14: 15199.97 | F14: 0.3 | G14: =D14/E14 -> 0.18822735 | H14: =D14/(D14+E14) -> 0.15841021 | I14: ='peers Levered Beta - regression'!E9 -> 1.2320998 | J14: =I14/(1+(1-F14)*(G14)) -> 1.088659
E16: Average | F16: =AVERAGE(F10:F14) -> 0.3 | G16: =AVERAGE(G10:G14) -> 0.39832877 | H16: =AVERAGE(H10:H14) -> 0.27150898 | I16: =AVERAGE(I10:I14) -> 1.3182471 | J16: =AVERAGE(J10:J14) -> 1.0342229
E17: Median | F17: =MEDIAN(F10:F14) -> 0.3 | G17: =MEDIAN(G10:G14) -> 0.40158987 | H17: =MEDIAN(H10:H14) -> 0.28652452 | I17: =MEDIAN(I10:I14) -> 1.3052257 | J17: =MEDIAN(J10:J14) -> 1.053386
B20: Cost of Debt | G20: Cost of Equity
B22: Pre tax cost of Debt | E22: ='WACC input data'!C10+(0.75*'WACC input data'!C11)+'WACC input data'!C12 -> 0.068055 | G22: Risk-Free Rate | J22: ='WACC input data'!C10 -> 0.04008
B23: tax Rate | E23: =F17 -> 0.3 | G23: Market Risk Premium | J23: ='WACC input data'!C7 -> 0.0726
B24: Post Tax cost of Debt | E24: =E22*(1-E23) -> 0.0476385 | G24: Levered Beta 4 | J24: =J32 -> 1.3282043
G25: cost of equity | J25: =J22+(J24*J23) -> 0.13650763
B27: Capital structure | G27: Levered Beta
D28: Current | E28: Target
B29: Total Debt | C29: =D10 -> 98752 | D29: =C29/C31 -> 0.28652452 | E29: =H16 -> 0.27150898 | G29: comps Median Unlevered Beta | J29: =J17 -> 1.053386
B30: Market Capitalization | C30: =E10 -> 245902.62 | D30: =C30/C31 -> 0.71347548 | E30: =E31-E29 -> 0.72849102 | G30: Target Debt/Equity | J30: =E33 -> 0.37270052
B31: Total Capital | C31: =C29+C30 -> 344654.62 | D31: =D29+D30 -> 1 | E31: 1 | G31: Tax rate | J31: =E23 -> 0.3
G32: Levered Beta | J32: =J29*(1+((1-J31)*J30)) -> 1.3282043
B33: Debt / Equity | D33: =D29/D30 -> 0.40158987 | E33: =E29/E30 -> 0.37270052
B35: Capital structure
D36: Total cost | E36: Total Weight
B37: Debt | D37: =E24 -> 0.0476385 | E37: =E29 -> 0.27150898
B38: Equity | D38: =J25 -> 0.13650763 | E38: =E30 -> 0.72849102
A39: x | B39: Weighted average Cost of Capital | E39: =(D37*E37)+(D38*E38) -> 0.11237886
B42: Notes
B43: 1. Tax Rate Considered as Marginal Tax Rate of the country
B44: 2. Levered Beta is based on 3 year weekly data
B45: 3. Unlevered Beta = Levered Beta / (1+ (1- Tax rate ) * ( debt / Equity ))
B46: 4. Levered Beta = Unlevered Beta * (1+ (1- Tax rate ) * ( debt / Equity ))

Sheet peers Levered Beta - regression
B1: Peers Levered Beta - Regression | F1: Weekly Three Year data used for Regression
B4: Peer Name | C4: Total Debt | D4: Total Equity | E4: Levered Beta
B5: JSW Steel | C5: 98752 | D5: 245902.62 | E5: =SLOPE($G$14:$G$193,$E$14:$E$193) -> 1.1292529
B6: Tata Steel | C6: 94801.05 | D6: 189712.16 | E6: =SLOPE(I14:I193,$E$14:$E$193) -> 1.3540647
B7: Jindal Steel | C7: 18406.08 | D7: 91711.02 | E7: =SLOPE($K$14:$K$193,$E$14:$E$193) -> 1.3052257
B8: S A I L | C8: 36933.94 | D8: 52655.94 | E8: =SLOPE($M$14:$M$193,$E$14:$E$193) -> 1.5705924
B9: Sarda Energy | C9: 2861.05 | D9: 15199.97 | E9: =SLOPE($O$14:$O$193,$E$14:$E$193) -> 1.2320998
D11: Nifty | F11: JSTL | H11: TISC | J11: JNSP | L11: SAIL | N11: SAEM
B12: Date | D12: Price | E12: Growth | F12: Price | G12: Growth | H12: Price | I12: Growth | J12: Price | K12: Growth | L12: Price | M12: Growth | N12: Price | O12: Growth
B13: 15-06-2025 | D13: 25112.4 | F13: 1005.55 | H13: 151.97 | J13: 899.05 | L13: 127.48 | N13: 431.35
B14: 45875 | D14: 24718.6 | E14: =D14/D13-1 -> -0.015681496 | F14: 987.25 | G14: =F14/F13-1 -> -0.018198996 | H14: 152.13 | I14: =H14/H13-1 -> 0.0010528394 | J14: 920.75 | K14: =J14/J13-1 -> 0.024136589 | L14: 129.35 | M14: =L14/L13-1 -> 0.014668968 | N14: 448.95 | O14: =N14/N13-1 -> 0.040802133
B15: 45663 | D15: 25003.05 | E15: =D15/D14-1 -> 0.011507529 | F15: 1004.9 | G15: =F15/F14-1 -> 0.017877944 | H15: 157.49 | I15: =H15/H14-1 -> 0.035233024 | J15: 962.75 | K15: =J15/J14-1 -> 0.045614988 | L15: 135.04 | M15: =L15/L14-1 -> 0.043989177 | N15: 435.95 | O15: =N15/N14-1 -> -0.028956454
B16: 25-05-2025 | D16: 24750.7 | E16: =D16/D15-1 -> -0.010092769 | F16: 993.5 | G16: =F16/F15-1 -> -0.011344412 | H16: 161.02 | I16: =H16/H15-1 -> 0.022414122 | J16: 948.9 | K16: =J16/J15-1 -> -0.014385874 | L16: 129.18 | M16: =L16/L15-1 -> -0.04339455 | N16: 437.1 | O16: =N16/N15-1 -> 0.0026379172
B17: 18-05-2025 | D17: 24853.15 | E17: =D17/D16-1 -> 0.0041392769 | F17: 1008.5 | G17: =F17/F16-1 -> 0.015098138 | H17: 162.97 | I17: =H17/H16-1 -> 0.012110297 | J17: 953.4 | K17: =J17/J16-1 -> 0.0047423332 | L17: 125.92 | M17: =L17/L16-1 -> -0.025236105 | N17: 469.4 | O17: =N17/N16-1 -> 0.073896134
B18: 45966 | D18: 25019.8 | E18: =D18/D17-1 -> 0.0067053874 | F18: 1021.8 | G18: =F18/F17-1 -> 0.013187903 | H18: 157.55 | I18: =H18/H17-1 -> -0.033257655 | J18: 981.6 | K18: =J18/J17-1 -> 0.029578351 | L18: 122.48 | M18: =L18/L17-1 -> -0.027318933 | N18: 454.75 | O18: =N18/N17-1 -> -0.031210055
B19: 45752 | D19: 24008 | E19: =D19/D18-1 -> -0.040439972 | F19: 957 | G19: =F19/F18-1 -> -0.063417499 | H19: 142.78 | I19: =H19/H18-1 -> -0.093748017 | J19: 855.35 | K19: =J19/J18-1 -> -0.12861654 | L19: 109.01 | M19: =L19/L18-1 -> -0.10997714 | N19: 421.4 | O19: =N19/N18-1 -> -0.073336998
B20: 27-04-2025 | D20: 24346.7 | E20: =D20/D19-1 -> 0.014107797 | F20: 973.2 | G20: =F20/F19-1 -> 0.0169279 | H20: 141.18 | I20: =H20/H19-1 -> -0.011206051 | J20: 897.75 | K20: =J20/J19-1 -> 0.049570351 | L20: 113.22 | M20: =L20/L19-1 -> 0.03862031 | N20: 442.2 | O20: =N20/N19-1 -> 0.049359279
B21: 20-04-2025 | D21: 24039.35 | E21: =D21/D20-1 -> -0.012623887 | F21: 1028.4 | G21: =F21/F20-1 -> 0.056720099 | H21: 138.85 | I21: =H21/H20-1 -> -0.016503754 | J21: 891.8 | K21: =J21/J20-1 -> -0.0066276803 | L21: 114.81 | M21: =L21/L20-1 -> 0.014043455 | N21: 477.25 | O21: =N21/N20-1 -> 0.079262777
B22: 13-04-2025 | D22: 23851.65 | E22: =D22/D21-1 -> -0.0078080314 | F22: 1007.2 | G22: =F22/F21-1 -> -0.020614547 | H22: 137.14 | I22: =H22/H21-1 -> -0.012315448 | J22: 881.7 | K22: =J22/J21-1 -> -0.011325409 | L22: 113.96 | M22: =L22/L21-1 -> -0.0074035363 | N22: 479.1 | O22: =N22/N21-1 -> 0.0038763751
B23: 45812 | D23: 22828.55 | E23: =D23/D22-1 -> -0.042894307 | F23: 990.25 | G23: =F23/F22-1 -> -0.016828832 | H23: 133.42 | I23: =H23/H22-1 -> -0.027125565 | J23: 805.65 | K23: =J23/J22-1 -> -0.086253828 | L23: 108.34 | M23: =L23/L22-1 -> -0.049315549 | N23: 467.65 | O23: =N23/N22-1 -> -0.023898977
B24: 30-03-2025 | D24: 22904.45 | E24: =D24/D23-1 -> 0.0033247841 | F24: 1005.75 | G24: =F24/F23-1 -> 0.015652613 | H24: 140.39 | I24: =H24/H23-1 -> 0.052241043 | J24: 850.1 | K24: =J24/J23-1 -> 0.055172842 | L24: 112.6 | M24: =L24/L23-1 -> 0.039320657 | N24: 495.75 | O24: =N24/N23-1 -> 0.060087672
B25: 23-03-2025 | D25: 23519.35 | E25: =D25/D24-1 -> 0.026846312 | F25: 1063.2 | G25: =F25/F24-1 -> 0.057121551 | H25: 154.24 | I25: =H25/H24-1 -> 0.09865375 | J25: 912.3 | K25: =J25/J24-1 -> 0.073167863 | L25: 115.18 | M25: =L25/L24-1 -> 0.022912966 | N25: 513.9 | O25: =N25/N24-1 -> 0.036611195
B26: 16-03-2025 | D26: 23350.4 | E26: =D26/D25-1 -> -0.0071834468 | F26: 1058.7 | G26: =F26/F25-1 -> -0.0042325056 | H26: 157.28 | I26: =H26/H25-1 -> 0.019709544 | J26: 914.3 | K26: =J26/J25-1 -> 0.0021922613 | L26: 115.3 | M26: =L26/L25-1 -> 0.0010418475 | N26: 545.55 | O26: =N26/N25-1 -> 0.061587858
B27: 45903 | D27: 22397.2 | E27: =D27/D26-1 -> -0.040821571 | F27: 1001.2 | G27: =F27/F26-1 -> -0.054311892 | H27: 150.88 | I27: =H27/H26-1 -> -0.04069176 | J27: 889.7 | K27: =J27/J26-1 -> -0.02690583 | L27: 105.89 | M27: =L27/L26-1 -> -0.081613183 | N27: 541.05 | O27: =N27/N26-1 -> -0.0082485565
B28: 45691 | D28: 22552.5 | E28: =D28/D27-1 -> 0.0069339025 | F28: 1011.15 | G28: =F28/F27-1 -> 0.0099380743 | H28: 151.56 | I28: =H28/H27-1 -> 0.0045068929 | J28: 908.95 | K28: =J28/J27-1 -> 0.021636507 | L28: 110.91 | M28: =L28/L27-1 -> 0.047407687 | N28: 471.05 | O28: =N28/N27-1 -> -0.12937806
B29: 23-02-2025 | D29: 22124.7 | E29: =D29/D28-1 -> -0.018969072 | F29: 950.7 | G29: =F29/F28-1 -> -0.059783415 | H29: 137.2 | I29: =H29/H28-1 -> -0.094747955 | J29: 856.15 | K29: =J29/J28-1 -> -0.058089004 | L29: 105.02 | M29: =L29/L28-1 -> -0.053106122 | N29: 453.55 | O29: =N29/N28-1 -> -0.037151046
B30: 16-02-2025 | D30: 22795.9 | E30: =D30/D29-1 -> 0.030337135 | F30: 981.9 | G30: =F30/F29-1 -> 0.032817924 | H30: 140.76 | I30: =H30/H29-1 -> 0.025947522 | J30: 880.35 | K30: =J30/J29-1 -> 0.028266075 | L30: 112.76 | M30: =L30/L29-1 -> 0.073700248 | N30: 489.65 | O30: =N30/N29-1 -> 0.079594312
B31: 45902 | D31: 22929.25 | E31: =D31/D30-1 -> 0.0058497361 | F31: 964.6 | G31: =F31/F30-1 -> -0.017618902 | H31: 134.47 | I31: =H31/H30-1 -> -0.04468599 | J31: 833.3 | K31: =J31/J30-1 -> -0.053444653 | L31: 105.71 | M31: =L31/L30-1 -> -0.062522171 | N31: 458.05 | O31: =N31/N30-1 -> -0.064535893
B32: 45690 | D32: 23559.95 | E32: =D32/D31-1 -> 0.027506351 | F32: 980.75 | G32: =F32/F31-1 -> 0.016742691 | H32: 138.31 | I32: =H32/H31-1 -> 0.028556555 | J32: 844.55 | K32: =J32/J31-1 -> 0.01350054 | L32: 110.32 | M32: =L32/L31-1 -> 0.043609876 | N32: 466.25 | O32: =N32/N31-1 -> 0.017901976
B33: 26-01-2025 | D33: 23508.4 | E33: =D33/D32-1 -> -0.0021880352 | F33: 945 | G33: =F33/F32-1 -> -0.036451695 | H33: 134.62 | I33: =H33/H32-1 -> -0.026679199 | J33: 791.55 | K33: =J33/J32-1 -> -0.062755313 | L33: 107.43 | M33: =L33/L32-1 -> -0.026196519 | N33: 473.2 | O33: =N33/N32-1 -> 0.014906166
B34: 19-01-2025 | D34: 23092.2 | E34: =D34/D33-1 -> -0.01770431 | F34: 932.45 | G34: =F34/F33-1 -> -0.013280423 | H34: 129.74 | I34: =H34/H33-1 -> -0.036250186 | J34: 882.8 | K34: =J34/J33-1 -> 0.11528015 | L34: 108.17 | M34: =L34/L33-1 -> 0.0068882063 | N34: 431.2 | O34: =N34/N33-1 -> -0.088757396
B35: 45992 | D35: 23203.2 | E35: =D35/D34-1 -> 0.0048068179 | F35: 908.6 | G35: =F35/F34-1 -> -0.025577779 | H35: 130.28 | I35: =H35/H34-1 -> 0.0041621705 | J35: 924.65 | K35: =J35/J34-1 -> 0.047405981 | L35: 108.82 | M35: =L35/L34-1 -> 0.0060090598 | N35: 426.85 | O35: =N35/N34-1 -> -0.010088126
B36: 45778 | D36: 23431.5 | E36: =D36/D35-1 -> 0.0098391601 | F36: 900.1 | G36: =F36/F35-1 -> -0.0093550517 | H36: 127.43 | I36: =H36/H35-1 -> -0.021875959 | J36: 917.7 | K36: =J36/J35-1 -> -0.0075163575 | L36: 106.03 | M36: =L36/L35-1 -> -0.025638669 | N36: 470.65 | O36: =N36/N35-1 -> 0.10261216
B37: 29-12-2024 | D37: 24004.75 | E37: =D37/D36-1 -> 0.02446493 | F37: 915.05 | G37: =F37/F36-1 -> 0.016609266 | H37: 138.36 | I37: =H37/H36-1 -> 0.085772581 | J37: 957.85 | K37: =J37/J36-1 -> 0.043750681 | L37: 114.17 | M37: =L37/L36-1 -> 0.076770725 | N37: 481.15 | O37: =N37/N36-1 -> 0.022309572
B38: 22-12-2024 | D38: 23813.4 | E38: =D38/D37-1 -> -0.007971339 | F38: 913.3 | G38: =F38/F37-1 -> -0.0019124638 | H38: 138.91 | I38: =H38/H37-1 -> 0.0039751373 | J38: 923.55 | K38: =J38/J37-1 -> -0.035809365 | L38: 115.53 | M38: =L38/L37-1 -> 0.011912061 | N38: 478.3 | O38: =N38/N37-1 -> -0.0059233087
B39: 15-12-2024 | D39: 23587.5 | E39: =D39/D38-1 -> -0.0094862556 | F39: 917.35 | G39: =F39/F38-1 -> 0.0044344684 | H39: 140.68 | I39: =H39/H38-1 -> 0.012742063 | J39: 908.05 | K39: =J39/J38-1 -> -0.016783065 | L39: 116.1 | M39: =L39/L38-1 -> 0.0049337834 | N39: 469.6 | O39: =N39/N38-1 -> -0.018189421
B40: 45516 | D40: 24768.3 | E40: =D40/D39-1 -> 0.050060413 | F40: 999.85 | G40: =F40/F39-1 -> 0.089932959 | H40: 148.95 | I40: =H40/H39-1 -> 0.058785897 | J40: 998.75 | K40: =J40/J39-1 -> 0.099884368 | L40: 124.76 | M40: =L40/L39-1 -> 0.07459087 | N40: 478.15 | O40: =N40/N39-1 -> 0.018206985
B41: 45303 | D41: 24677.8 | E41: =D41/D40-1 -> -0.003653864 | F41: 1003.8 | G41: =F41/F40-1 -> 0.0039505926 | H41: 148.29 | I41: =H41/H40-1 -> -0.0044310171 | J41: 949.1 | K41: =J41/J40-1 -> -0.04971214 | L41: 123.89 | M41: =L41/L40-1 -> -0.0069733889 | N41: 472.5 | O41: =N41/N40-1 -> -0.011816376
B42: 24-11-2024 | D42: 24131.1 | E42: =D42/D41-1 -> -0.022153514 | F42: 966 | G42: =F42/F41-1 -> -0.037656904 | H42: 144.54 | I42: =H42/H41-1 -> -0.025288286 | J42: 906.45 | K42: =J42/J41-1 -> -0.044937309 | L42: 117.11 | M42: =L42/L41-1 -> -0.054725967 | N42: 447 | O42: =N42/N41-1 -> -0.053968254
B43: 17-11-2024 | D43: 23907.25 | E43: =D43/D42-1 -> -0.0092764109 | F43: 977.35 | G43: =F43/F42-1 -> 0.011749482 | H43: 142.78 | I43: =H43/H42-1 -> -0.01217656 | J43: 878.95 | K43: =J43/J42-1 -> -0.030338132 | L43: 112.83 | M43: =L43/L42-1 -> -0.036546836 | N43: 414 | O43: =N43/N42-1 -> -0.073825503
...

Sheet WACC input data
B1: Other Input Calculations
B3: Cost of equity Inputs
B4: 10 Year Govt. bond Yeild ( India ) | C4: 0.06188
B5: India country default spread | C5: 0.0218
B6: Mature market Base premium ( US ) | C6: 0.0433
B7: Equity risk premium ( India) | C7: 0.0726
B9: Cost of Debt Inputs
B10: Risk- free rate | C10: =C4-C5 -> 0.04008
B11: Country Risk Premium | C11: 0.0293
B12: Company default spread | C12: 0.006
